Workbook

Sheet 2025
A1: Société de contact | B1: Date de l'envoi de l'offre | C1: Date de l'offre | D1: Type de société | F1: Pays | G1: Email du contact | H1: Langue | I1: Titre | J1: Nom du contact | K1: Prénom du contact | L1: Dates séjour (venu du groupe) | O1: Activités Villars X/Diablerets X | P1: Nombre de nuits | Q1: Nombre de pax | R1: Transmis par | S1: Type de séjour | U1: Catégorie hôtel - nb d'étoiles | V1: Station demandée | X1: Remarques sur l'offre et choix de l'hôtel | Y1: Relance faite | Z1: Retour effectué aux hôtels | AA1: Réservation effectuée | AB1: Contact entré dans Brevo | AC1: Suivis de la demande (toute information nécessaire à avoir sur le processus - bien noter les dates) | AD1: Traité par | AE1: Disponibilité Villars | AO1: Disponibilité Les Diablerets
B2: jour | C2: mois | D2: Agence | E2: Entreprise | L2: jours | M2: mois | N2: année | S2: Incentive / Groupe | T2: Séminaire | V2: Villars | W2: Diablerets | AE2: Royalp | AF2: Palace | AG2: Victoria | AH2: Alpe Fleurie | AI2: VIU | AJ2: Ecureuil | AK2: Lavey | AL2: Miroir d'Argentine & Refuge | AM2: Les Mazots du Clos | AN2: Villars Lodge | AO2: The Glacier Hotel | AP2: Sources | AQ2: Poste | AR2: Lilas | AS2: Pillon
A3: BT Events | B3: 3 | C3: Janvier | D3: 1 | F3: PL | G3: dominika.makos@btevents.pl | H3: EN | I3: Mme | J3: Makos | K3: Dominika | L3: 26-30 | M3: Mars | N3: 2025 | O3: oui | P3: 4 | Q3: 14 | R3: DIRECT | S3: 1 | U3: 4* | V3: 1 | X3: L'agence a demandé une offre en direct au VIU. Ils ne nous ont contacté que pour les activités. Nous avons également reçu la demande de Vaud Promotion le 07.01.25. VX leur envoie une offre le 07.01.25. | Y3: le 05.03.2025 à VX - en attente du client GC | AA3: Pas de réponses | AB3: oui | AC3: Demande transmise à VX pour les activités. | AD3: MP | AI3: 1
A4: Blue Sky Travel | B4: 10 | C4: Janvier | E4: 1 | F4: BE | G4: holiday@blueskytravel.be | H4: BE | I4: Mme | J4: Outers | K4: Joëlle | L4: 18-21 | M4: Décembre | N4: 2025 | O4: oui | P4: 3 | Q4: 25 | R4: SCIB BE | S4: 1 | V4: 1 | X4: Demande d'offre faite par le SCIB BE auprès du Glacier Hotel mais fermé donc attente un retour de l'hôtel des Sources mais ils nous ont demandé de contacter le Victoria | Y4: le 05.03.2025 GC | AA4: Pas de réponses | AB4: oui | AD4: GC | AG4: 1 | AO4: fermé | AP4: le client attend directement un retour de leur part
A5: Nestlé Health Science | B5: 28 | C5: Janvier | E5: 1 | F5: CH | G5: melisa.dakaj@nestle.com | H5: CH | I5: Mme | J5: Dakaj | K5: Melisa | L5: 13 | M5: Mars | N5: 2025 | O5: oui | P5: 0 | Q5: 50 | R5: DIRECT | S5: 1 | V5: 1 | Y5: le 05.03.2025 à VX GC | AA5: Activité only confirmé | AB5: oui | AC5: transmis la demande à VX le 28.01.25 | AD5: GC
A6: Sportlag | B6: 29 | C6: Janvier | D6: 1 | F6: FR | G6: flavie@spotlag.com | H6: FR | I6: Mme | J6: Garnier | K6: Flavie | L6: 04-06 | M6: Mars | N6: 2026 | O6: oui | P6: 0 | Q6: 100 | R6: DIRECT | S6: 1 | U6: - | V6: 1 | W6: 1 | X6: Devrait loger à Lausanne | Y6: le 05.03.2025 à VX - demande déclinée GC | Z6: - | AA6: Activité only décliné | AB6: oui | AC6: Contact rencontré lors d'Eductour Partance 2024. Demande d'activité only, car logement à Lausanne. VX répond par la négative. VSS a envoyé une offre. | AD6: MP
A7: Les 3 Vallées | B7: 11 | C7: Février | E7: 1 | F7: FR | G7: quentin.reinhart@les3vallees.com | H7: FR | I7: M | J7: Quentin | K7: Reinhart | L7: 19-21 | M7: Mai | N7: 2025 | O7: oui | P7: 2 | Q7: 12 | R7: DIRECT | T7: 1 | V7: 1 | W7: 1 | Y7: le 05.03.2025 GC | AA7: Pas de réponses | AB7: oui | AC7: Eu le client au téléphone le 10.02. Ils seraient interressés à rencontrer le département Promotion lors de leur venu. | AD7: GC | AI7: 1 | AJ7: 1 | AS7: 1
A8: Genedis | B8: 12 | C8: Février | E8: 1 | F8: CH | G8: celine.gex@genedis.ch | H8: FR | I8: Mme | J8: Gex | K8: Céline | L8: 20 | M8: Septembre | N8: 2025 | O8: oui | P8: 0 | Q8: 150 | R8: DIRECT | S8: 1 | U8: - | V8: 1 | X8: Journée récréative pour nos collaborateurs et leurs familles | Y8: le 05.03.2025 à VX - en attente du client GC | AA8: Oui/activity only | AB8: oui | AD8: MP
A9: Movis | B9: 14 | C9: Février | E9: 1 | F9: CH | G9: jolanda.arbore@movis.ch | H9: EN | I9: Mme | J9: Arbore | K9: Jolanda | L9: 29-30 | M9: Août | N9: 2025 | O9: non | P9: 1 | Q9: 85 | R9: DIRECT | S9: 1 | V9: 1 | Y9: le 07.03.2025 GC | AA9: Offres déclinées | AB9: oui | AC9: Demande transmise par Sergei --> c'est sa belle sœur 11.03.2025 : ils hésitent entre Villars et Bâle, ils reveinnent vers nous au plus vite | AD9: GC | AG9: 1 | AI9: 1 | AJ9: 1
A10: Btafirst | B10: 19 | C10: Février | D10: 1 | F10: CH | G10: mice@btafirst.com | H10: DE | I10: Mme | J10: Ineichen | K10: Tiffany | L10: 12-15 | M10: Janvier | N10: 2026 | O10: non | P10: 3 | Q10: 140 | R10: AUTRE | T10: 1 | V10: 1 | Y10: le 07.03.2025 LK | AA10: Pas de réponses | AB10: oui | AC10: La cliente est en contact avec Jesus voir dans le serveur | AD10: LK | AG10: 1 | AI10: 1 | AN10: 1
A11: Philip Morris Products SA | B11: 26 | C11: Février | E11: 1 | F11: CH | G11: natalie.birtele@pmi.com | H11: FR | I11: Mme | J11: Birtele | K11: Natalie | M11: Mars | N11: 2025 | O11: oui | P11: 1 | Q11: 6 | R11: DIRECT | T11: 1 | U11: 4-5* | V11: 1 | W11: 1 | X11: The Glacier Hotel - Complet Palace - Fermé | AA11: Pas d'offre | AB11: oui | AD11: LK | AE11: 1 | AF11: 1 | AG11: 1 | AI11: 1 | AN11: 1
A12: EPFL | B12: 4 | C12: Mars | E12: 1 | F12: CH | G12: sabrina.martone@epfl.ch | H12: FR | I12: Mme | J12: Martone | K12: Sabrina | L12: 16 | M12: Avril | N12: 2025 | O12: oui | P12: 0 | Q12: 30 | R12: DIRECT | S12: 1 | W12: 1 | Y12: le 26.03.2025 GC | AA12: Activité only confirmé | AB12: oui | AD12: LK
A13: ARX c/o Pini Groupe SA | B13: 6 | C13: Mars | E13: 1 | F13: CH | G13: jessica.favre@arx.ing | H13: FR | I13: Mme | J13: Favre | K13: Jessica | L13: 21 | M13: Mars | N13: 2025 | O13: oui | P13: 0 | Q13: ? | R13: DIRECT | S13: 1 | V13: 1 | AA13: Activité only confirmé | AB13: oui | AC13: A demandé qu'on lui envoie la carte des randonnées hivernales pour une rando "autour du lac de bretaye" | AD13: GC
A14: Flyability SA | B14: 23 | C14: Octobre | E14: 1 | F14: CH | G14: vanessa.demelo@flyability.com | H14: FR | I14: Mme | J14: De Melo | K14: Vanessa | L14: 29-30 | M14: Janvier | N14: 2026 | O14: oui | P14: 1 | Q14: 120-150 | R14: DIRECT | S14: 1 | T14: 1 | U14: 3*-4* | V14: 1 | W14: 1 | X14: • Chalet avec grande chambres/dortoirs avec petit-déjeuner pour 100 personnes • Hotel pouvant être réservé pour 100 personnes | Y14: le 26.03.2025 GC | AA14: En cours | AB14: oui | AC14: MP a appelé le 29.04.25. C'est toujours en suspens. Ce sera probablement la semaine avant, mais pas besoin de faire une nouvelle offre. Ils nous redonneront des nouvelles courant mai. 21.10 : l'entreprise souhaite une nouvelle offre à d'autres dates 29-30 janvier 2026 23.10 : envoi de l'offre à la cliente avec le lodge et le VIU pouvant l'acceuillir au dates voulu et le Victoria avec des propos de dates (eu le directeur au téléphone) | AD14: GC | AG14: 1 | AI14: 1 | AN14: 1
A15: Finass - Travel is our Business | B15: 14 | C15: Mars | D15: 1 | F15: CH | G15: Natalie.Buff@finass.ch | H15: DE | I15: Mme | J15: Buff | K15: Natalie | L15: 5-7 | M15: Septembre | N15: 2025 | O15: oui | P15: 2 | Q15: 70 | R15: DIRECT | S15: 1 | T15: 1 | V15: 1 | X15: On pris directement contact avec le VAR ainsi qu'avec VX | Y15: le 26.03.2025 GC | AA15: Pas de réponses | AB15: oui | AC15: 13.03 : VX leur a proposé une chasse au trésor dans le vignoble avec dégustation de vin L'agence organise elle-même une activité sur le Glacier 3000 27.03 : retour du VAR - La demande n'est pas encore confirmée. Nous sommes déjà en contact pour l'hébergement et je lui ai déjà envoyé des idées d'activités dans la region. Mais elle ne confirmera que si nous pouvons lui offrir des expériences UNIQUES pour cette groupe, avec un très bon budget. Nous sommes en compétition avec Genève, | AD15: GC | AF15: 1
A16: Joubert Events | B16: 17 | C16: Mars | D16: 1 | F16: FR | G16: chefdeprojet@joubert-events.com | H16: FR | I16: Mme | J16: Catalano | K16: Léna | L16: 13-16 20-23 27-30 | M16: Janvier | N16: 2026 | O16: oui | P16: 3 | Q16: 28 | R16: DIRECT | S16: 1 | T16: 1 | U16: privatisation de l'hôtel obligatoire | V16: 1 | W16: 1 | X16: Privilégié les petits hôtels pour les privatiser. L'Ecureuil aura des travaux début 2026, ne pouvait donc pas se prononcer sur ce seminaire | Y16: le 26.03.2025 GC | Z16: oui | AA16: Offres déclinées | AB16: oui | AD16: GC | AH16: 1 | AN16: 1 | AP16: 1
A17: At Home Events | B17: 23 | C17: Mars | E17: 1 | F17: UK | G17: claire@athome-events.co.uk | H17: EN | I17: Mme | J17: Ashby | K17: Claire | M17: Avril | N17: 2026 | O17: oui | P17: 4 | Q17: 16-20 | R17: SCIB UK | S17: 1 | T17: 1 | U17: Luxury retreat centre, boutique hotel, wellness resort, or mountain lodge (high-end 4/5* standard). Single occupancy. Ideally with designated workspace in each room as women are business owners. | V17: 1 | Y17: le 10.04.2025 GC | AA17: Pas de réponses | AB17: déjà dans Brevo | AD17: GC | AE17: 1 | AF17: 1 | AG17: 1 | AI17: 1
A18: Pur'Events | B18: 2 | C18: Avril | D18: 1 | F18: FR | G18: pauline@purevents.fr | H18: FR | I18: Mme | J18: Soler | K18: Pauline | L18: 15-18 | M18: Mars | N18: 2026 | O18: oui | P18: 1 | Q18: 190 | R18: SCIB FR | S18: 1 | T18: 1 | U18: 4* : privilégié Palace et Victoria | V18: 1 | Y18: le 15.04.2025 GC | Z18: oui | AA18: Offres déclinées | AB18: oui | AD18: GC | AF18: 1 | AG18: 1 | AI18: 1
A19: American Express Global Business Travel | B19: 3 | C19: Avril | D19: 1 | F19: UK | G19: nadia.biondi@amexgbt.com | H19: EN | I19: Mme | J19: Biondi | K19: Nadia | L19: 31-4 | M19: Mars | N19: 2026 | O19: oui | P19: 2 | Q19: 18 | R19: SCIB FR | S19: 1 | U19: Type boutique-hôtel, privilégier établissement avec piscine et/ou spa. 5* ne rentreront pas dans le budget. | V19: 1 | W19: 1 | X19: Prévoir un repérage de 2 nuits dans l’offre. Budget : autour de 550€ pax/jour sans le transport. | Y19: le 16.04.2025 GC | Z19: oui | AA19: Offres déclinées | AB19: oui | AD19: GC | AG19: 1 | AH19: 1 | AI19: 1 | AO19: 1 | AP19: 1
A20: Direction générale du territoire et du logement | B20: 3 | C20: Avril | E20: 1 | F20: CH | G20: stephane.oppliger@vd.ch | H20: FR | I20: M | J20: Oppliger | K20: Stéphane | L20: 19 | M20: Juin | N20: 2025 | O20: oui | P20: 0 | Q20: 150 | R20: DIRECT | T20: 1 | U20: no rep | V20: 1 | W20: 1 | X20: Demande simplement une salle de séminaire. Pas de logements ni d'activités. | Y20: le 16.04.2025 GC | AA20: Activité only no rép | AB20: oui | AC20: VX leur a envoyé plusieurs lieu pour un lunch mais l'entreprise préfère réserver eu en direct avec le restaurant. | AD20: GC
A21: Agence VMIS | B21: 22 | C21: Avril | D21: 1 | F21: FR | G21: pmillion@vmis.fr | H21: FR | I21: M | J21: Million | K21: Patrice | L21: 10-12 | M21: Juin | N21: 2025 | O21: non | P21: 2 | Q21: 220 | R21: SCIB FR | T21: 1 | U21: 4/5* sur un seul établissement Avec un espace de sémianire ainsi qu'il salle pour un bureau | V21: 1 | X21: Il a été discuté d’un combo Victoria/Villars Palace. Pas connaissance du budget total, mais la chambre doit être à 200 par nuitée max. | Y21: le 08.05.2025 GC | Z21: oui | AA21: Pas de réponses | AB21: déjà dans Brevo | AD21: GC | AF21: 1 | AG21: 1
A22: Moma Event - essai presse Citroën 2025 | B22: 23 | C22: Avril | D22: 1 | F22: FR | G22: camilleplanqueraillard@gmail.com | H22: FR | I22: Mme | J22: Raillard | K22: Camille | L22: 3-25 | M22: Septembre | N22: 2025 | O22: non | P22: 23 | Q22: 54 | R22: SCIB FR | T22: 1 | U22: Hôtel : 4* à 1h30 d’un aéroport max. Proche nature pour un départ fluide en voiture depuis l’hôtel. Pas d’hôtel belle époque ni aéroport, il s’agit d’un modèle de voiture familial donc valoriser des hôtels « comme à la maison » : pas + de 100 chambres en tout dans l’hôtel. | V22: 1 | X22: Demande sur 23 nuitées avec : hébérgement, espaces de réunion, logistique automobile, restauration | Y22: faire d'abord une relance à l'hôtel et tenir Mel au jus | Z22: oui | AA22: Offres déclinées | AB22: oui | AC22: 24.04.2025 : L’hôtel pourrait en effet tout à fait convenir pour ce lancement automobile. La cliente fait le point et prendre contact le Victoria 30.04.2025 : Eu Sandra Hubert au téléphone, en attente d'un retour du client. L'équipe MICE a passé beaucoup de temps sur le dossier et au téléphone avec la cliente. | AD22: GC | AG22: 1 | AI22: suite à un tel avec William, pas la dispo d'acceuillir ce groupe
A23: INVENTEC PERFORMANCE CHEMICALS SA | B23: 24 | C23: Avril | E23: 1 | F23: CH | G23: vquercia@inventec.dehon.com | H23: FR | I23: M Mme | J23: Quercia Bouchard-Mona | K23: Victorio Peggy | L23: 3-7 | M23: Décembre | N23: 2025 | O23: non | P23: 4 | Q23: 50-60 | R23: SCIB FR | T23: 1 | U23: minimum 3 étoiles Préférence en chambre single | X23: Infrastructure souhaitée dans la salle de réunion (nombre de places, mode de disposition des sièges comme style de séminaire ou style de théâtre) : 50 à 60 places en style classe avec système de visio conférence, micro Nombre de jours ou dates concrète : Disons arrivée le 3 décembre après-midi, réunion (écran, projecteur, micros, système visio, déjeuner et pauses,...) les 4 et 5, profiter des montagnes et du ski le 6 et départ le 7. | Y23: le 08.05.2025 GC | Z23: oui | AA23: Séjours confirmés | AB23: oui | AD23: GC | AG23: 1 | AI23: 1
A24: QTP Events | B24: 24 | C24: Avril | D24: 1 | F24: UK | G24: charlotte@qtpevents.com | H24: EN | I24: Mme | J24: Carrier | K24: Charlotte | L24: 3-6 | M24: Février | N24: 2026 | O24: non | P24: 3 | Q24: 100 | R24: SCIB UK | T24: 1 | U24: Demande spécifique pour le Victoria | V24: 1 | Y24: le 08.05.2025 GC | Z24: oui | AA24: Pas de réponses | AB24: oui | AD24: GC | AG24: 1 | AO24: 1
A25: ILO International Labour Organization | B25: 28 | C25: Avril | E25: 1 | F25: CH | G25: maino@ilo.org | H25: FR | I25: Mme | J25: Maino | K25: Barbara | L25: 30.11 au 03.12 | M25: Novembre | N25: 2025 | O25: non | P25: 3 | Q25: 35-40 | R25: DIRECT | T25: 1 | U25: 3-4* | V25: 1 | X25: Personne rencontrée lors de l'Afterwork SBE à Genève du 15 avril 2025 | Y25: le 14.05.2025 GC | Z25: oui | AA25: Pas de réponses | AB25: oui | AD25: GC | AG25: 1 | AI25: 1 | AN25: 1
A26: Cyrah Events | B26: 25 | C26: Avril | D26: 1 | F26: FR | G26: jocelyne.beltran@cyrah-events.com | H26: FR | I26: Mme | J26: Blazer Beltran | K26: Jocelyne | L26: 13-20 14-21 | M26: Février | N26: 2026 | O26: non | P26: 7 | Q26: 114 | R26: DIRECT | S26: 1 | U26: 100 étudiants et 14 profs Les profs en chambres individuelles et les étudiants en chambres partagées | V26: 1 | W26: 1 | X26: Personne rencontrée lors de l'Afterwork SBE à Genève du 15 avril 2026 | Z26: oui | AA26: En cours | AB26: oui | AC26: 13.05 : le client nous a écrit pour l'hébérgement, il a été renvoyé vers l'hôtel. En attente d'un échange entre eux. 28.05 : le Victoria a pris contact avec la cliente 24.06 : relance faites auprès du Victoria | AD26: GC
A27: VICTOR KYBURZ AG | B27: 6 | C27: Mai | E27: 1 | F27: CH | G27: l.unterrassner@kyburz-sapphire.ch | H27: FR | I27: Mme | J27: Unterrassner-Kyburz | K27: Lea | L27: 10-11 11-12 | M27: Juillet | N27: 2025 | O27: non | P27: 1 | Q27: 80 | R27: DIRECT | S27: 1 | U27: 3* | V27: 1 | W27: 1 | Y27: le 21.05.2025 GC | Z27: oui | AA27: Offres déclinées | AB27: oui | AD27: GC | AG27: 1 | AN27: 1
A28: Groupe S'cape TotalEnergies Global Services (TGHRS) | B28: 2 | C28: Juin | D28: 1 | F28: FR | G28: agathe.abitbol@groupe-scape.com | H28: FR | I28: Mme | J28: Abitbol | K28: Agathe | L28: 23-25 | M28: Mars | N28: 2026 | O28: oui | P28: 2 | Q28: 310 | R28: DIRECT | T28: 1 | U28: 3* - 4* - 5* | V28: 1 | Y28: le 16.06.2025 GC | Z28: oui | AA28: Pas de réponses | AB28: oui | AC28: 18.08 : reçu mail du VP pour avertir qu'ils ont annulés l'option car déjà un groupe à ces dates | AD28: LK | AE28: 1 | AF28: 1 | AG28: 1 | AI28: 1
A29: AO Havas Voyages M&E | B29: 17 | C29: Juin | D29: 1 | F29: FR | G29: mtourillon@havasvoyages-events.fr | H29: FR | I29: Mme | J29: Tourillon | K29: Mélanie | M29: Janvier | N29: 2026 | O29: oui | P29: 2 | Q29: 200 | R29: SCIB FR | T29: 1 | U29: 3-4* | V29: 1 | W29: 1 | X29: 3 options différentes pour le séjour | Z29: non | AA29: Pas d'offre | AB29: oui | AC29: Aucun hôtel n'a de la dispo - réponse négative envoyée à la cliente | AD29: GC | AG29: 1 | AN29: 1 | AO29: 1
A30: DCTN Ville de Genève | B30: 23 | C30: Juin | E30: 1 | F30: CH | G30: assistantes.dir.dctn@geneve.ch | H30: FR | I30: Mme | J30: Foletti | K30: Isabella | L30: 1-2 | M30: Octobre | N30: 2025 | O30: oui | P30: 1 | Q30: 31 | R30: DIRECT | T30: 1 | V30: 1 | W30: 1 | Z30: oui | AA30: Séjours confirmés | AB30: oui | AC30: 24.06 : Romain l'a eu au téléphone pour la confirmation de cette offre. Le Victoria doit encore revenir vers la cliente avec le meilleur devis. 08.07 : La cliente redemande un devis au Victoria pour avoir la gratuité des salles de séminaires 15.07 : reçu la confirmation de venue de la part de la cliente 18.07 : La cliente n'a finalement pas besoin des 3 salles de séminaire et à redemandé un devis à l'Hôtel. Le Victoria a renvoyé une V5 du devis | AD30: GC | AP30: 1
A31: TSM Versoix / TSM Meyrin | B31: 5 | C31: Août | D31: 1 | F31: CH | G31: s.pidancet@tsm-versoix.ch | H31: FR | I31: M | J31: Pidancet | K31: Simon | L31: 24 | M31: Août | N31: 2025 | O31: oui | R31: DIRECT (OT, AV, formulaire) | S31: 1 | V31: 1 | AA31: Activité only décliné | AB31: oui | AC31: 05.08 : info reçu par l'accueil. Vu que c'est une demande d'activité, j'ai transmis en ce jour à Villars Experience 07.08 : Le client décline car il a choisi une autre offre à Château D'Oex | AD31: LL
A32: Agence creative Spirit | B32: 5 | C32: Août | D32: 1 | F32: FR | G32: Mary@creativespirit.eu | H32: FR | I32: Mme | J32: Montiel | K32: Mary | L32: 25 | M32: Juin | N32: 2026 | P32: 7 | R32: SCIB FR | T32: 1 | U32: 4 | V32: 1 | X32: Demande de privatisation pour Villars Palace et Hotel Victoria - Villars Lodge pour loger 40 staffs | Z32: oui | AA32: Offres déclinées | AB32: oui | AC32: 06.08.25 : Villars Palace est dispo pour une privatisation partielle avec 90 chambres de dispo. Victoria peut avoir 120 chambres à dispo. 60 chambres sont dispo au Chalet Royalp et 46 chambres au Villars Lodge (logement des staffs). Étant donné que les exigences demandées par la cliente ne sont pas respectées au niveau de la privatisation, je l'ai contactée pour lui expliqué la situation. Je lui ai envoyé un mail récapitalif de notre appel et attend réponse de sa part si interêt il y a ou non 20.08.2025 : la cliente a choisi une autre destination car aucun hôtel pouvait être privatisé à ces dates, cela a été transmis à Myriam de VP | AD32: LL
A33: MCI/Ovation | B33: 11 | C33: Août | D33: 1 | F33: CH | G33: fiona.schaad@wearemci.com | H33: EN | I33: Mme | J33: Schaad | K33: Fiona | M33: Mai | N33: 2026 | O33: oui | Q33: 500 | R33: DIRECT (OT, AV, formulaire) | S33: 1 | V33: 1 | W33: 1 | X33: Pour l'instant seulement une demande pour des activités mais éventuellement de l'hébérgement. | Z33: oui | AA33: Pas d'offre | AB33: oui | AC33: 11.08 : demander à VX de nous laisser en cc dans les échanges avec la cliente afin qu'on puisse savoir si elle souhiate une offre d'hébégement ou si nous pourrions lui en proposer une. 19.08 : l'agence n'a proposer que des sites concrets et non des destinations à son client | AD33: GC
A34: La Roche Posay | B34: 11 | C34: Août | E34: 1 | F34: FR | G34: syan.perrin@gmail.com | H34: FR | I34: Mme | J34: Perrin | K34: Sylvie-Anne | M34: Avril | N34: 2026 | O34: oui | Q34: 300 | R34: SCIB FR | S34: 1 | U34: 06.008 : la cliente avise SCIB FR que finalement elle ne souhiate plus d'hôtel mais plutôt des tentes glamping pouvant acceuillir 300 personnes | V34: 1 | X34: 06.008 : la cliente avise SCIB FR que finalement elle ne souhiate plus d'hôtel mais plutôt des tentes glamping pouvant acceuillir 300 personnes | Z34: oui | AA34: Activité only décliné | AB34: déjà dans Brevo mais indiqué comme signalé | AC34: 11.08 : VX indique que pendant cette saison, tout les terrains seront utiliser pour les pistes de ski et encore enneigés. Mélanie a proposé les Whitepods sur recommandation de VX | AD34: MP
A35: KITES International Event Agency | B35: 15 | C35: Août | E35: 1 | F35: CH | G35: richard@kites-events.agency | H35: EN | I35: M | J35: Kemp | K35: Richard | L35: 29 | M35: Octobre | N35: 2025 | O35: oui | P35: 2 | Q35: 60 | R35: DIRECT (OT, AV, formulaire) | S35: 1 | T35: 1 | U35: Ils ont réservé l'hébergement directemen auprès du Villars Palace sans passer par nous | V35: 1 | Y35: - | Z35: - | AA35: Séjours confirmés | AB35: oui | AC35: Sur demande de Sergei, Mélanie a confirmé l'activité au client. 19.08 : le client prend contatc avec Guido pour l'organisation des activités à la suite du téléphone avec Sergei 20.08 : Sandra Marro a envoyé une offre de transport au client | AD35: MP | AF35: 1
A36: Agence Amirantes (Annecy) | B36: 21 | C36: Août | D36: 1 | F36: FR | G36: apagenel@amirantes.eu | H36: FR | I36: Mme | J36: Pagenel | K36: Alizée | L36: 8-11 | M36: Janvier | N36: 2026 | O36: oui | P36: 3 | Q36: 40 | R36: SCIB FR | S36: 1 | V36: 1 | X36: L'agence a déjà pris contact avec l'hôtel VIU sans passer par nous mais elle souhaiterait organiser une nuit insolite en refuge pour les 40 pers. Myriam de ST nous a écrit pour nous demander les lieux à dispo. J'ai répondu la MMB et ai mis VX et Guido en copie afin qu'ils puissent amener d'autres idées | Y36: Oui, le 15.09.2025 | AA36: Pas de réponses | AB36: oui | AC36: 26.08 : VX indique qu'il n'y a aucun lieu insolite pour accueillir le groupe de 40pax. Un retour a été fait à Myriam du SCIB FR. 26.08 : le client est interessé par The Glacier Hotel et une nuit à Solalex ou Bretaye 17.09 : SCIB reviens vers nous en disant que la cliente à mis le projet en sand-by. Myriam reviendra vers nous dés qu'il y a du nouveau | AD36: GC | AI36: 1
A37: Cosmology in the Alps - EPFL / LM Congress | B37: 26 | C37: Août | E37: 1 | F37: CH | G37: howard@lmcongress.ch | H37: FR | I37: M | J37: Howard | K37: Gérald | L37: 16-20 | M37: Mars | N37: 2026 | O37: non | P37: 4 | Q37: 120 | R37: DIRECT (OT, AV, formulaire) | T37: 1 | V37: 1 | X37: Était déjà venu l'année dernière pour leur séminaire et souhiate revenir pour encore 2 ans. Ils voudraient une activité différentes de ce qu'ils ont fait l'année dernière : Glacier 3000 | AA37: Séjours confirmés | AB37: oui | AC37: 26.08.2025 : demande initiale reçu par Sergei puis transmis à MP 15.09 : retour reçu de Henry Savioz des mines. Il indique que à cause des travaux il ne pourront pas acceuillir le groupe mais ils gardent contact pour 2026 10.10.2025 : Mel en contact 16.10.2025 : Hébérgement confirmé au Glacier Hotel et il y aura des activités | AD37: MP
A38: Inüi Collection | B38: 4 | C38: Septembre | D38: 1 | F38: CH | G38: estelle@inuicollection.com | H38: FR | I38: Mme | J38: Bernière | K38: Estelle | L38: 2 | M38: Octobre | N38: 2025 | O38: oui | P38: 3 | Q38: 15 | R38: DIRECT (OT, AV, formulaire) | T38: 1 | V38: 1 | W38: 1 | X38: Le groupe de personne va séjourner à Villars dès le 29 septembre et l'agence doit trouver une activité pour le 2 octobre dans l'après-midi à partir de 14h30 | Y38: Oui, le 10.10 | AA38: En cours | AB38: oui | AC38: 04.09 : envoie à la cliente différentes activités (pas directement envoyé chez VX) mais à proposer un certain choix 10.10 : la cliente a choisi une balade dans le Lavaux avec dégustation de vin | AD38: MP
A39: ZZZest | B39: 4 | C39: Septembre | D39: 1 | F39: CH | G39: emiguet@zzzest.com | H39: FR | I39: Mme | J39: Miguet | K39: Emilie | M39: Janvier Février Mars | N39: 2026 | O39: oui | P39: 3 | Q39: 16 | R39: DIRECT (OT, AV, formulaire) | S39: 1 | W39: 1 | X39: Possède déjà un hôtel ils veulent juste une proposition d'actiité pour le groupe sur les Diabelrets | Y39: Oui, le 10.10 à VX | AA39: Activité only no rép | AB39: oui | AC39: 04.09 : Transmis à VX | AD39: MP
A40: Senior Discovery Tours | B40: 12 | C40: Septembre | D40: 1 | F40: CAN | G40: Lseprus@stc.ca | H40: EN | I40: Mme | J40: Seprus | K40: Lise I. | L40: 15 29 | M40: Septembre | N40: 2025 | O40: oui | Q40: 32 | R40: DIRECT (OT, AV, formulaire) | S40: 1 | U40: aucune demande d'hôtel | V40: 1 | X40: Aucune demande d'hôtel mais loge sur Villars et voulait une activité autour de la desgustation de vin. Son loger et ont leur propore véhicule pour se déplacer. | AA40: Activité only confirmé | AB40: déjà dans Brevo | AC40: 12.09 : VX pas dispo ni Guido qui est à l'étranger ni Allison qui est en congé. Directement pris contact avec l'Abbaye de Salaz qui a montrer de l'intérêt. Janine assure la suite du suivis avec la dame 15.09.2025 : Téléphone avec Janine de l'Abbaye --> pas de réservation pour le 15.09 mais confirmer pour le 29.09 | AD40: GC
...

Sheet Statistiques
A1: Provenance des demandes
A2: CH | B2: =COUNTIF('2025'!F$3:F$123,Statistiques!A2) -> 25 | C2: =B2/B$13 -> 0.46296296
A3: FR | B3: =COUNTIF('2025'!F$3:F$123,Statistiques!A3) -> 20 | C3: =B3/B$13 -> 0.37037037
A4: BE | B4: =COUNTIF('2025'!F$3:F$123,Statistiques!A4) -> 2 | C4: =B4/B$13 -> 0.037037037
A5: NL | B5: =COUNTIF('2025'!F$3:F$123,Statistiques!A5) -> 0 | C5: =B5/B$13 -> 0
A6: LUX | B6: =COUNTIF('2025'!F$3:F$123,Statistiques!A6) -> 1 | C6: =B6/B$13 -> 0.018518519
A7: UK | B7: =COUNTIF('2025'!F$3:F$123,Statistiques!A7) -> 6 | C7: =B7/B$13 -> 0.11111111
A8: SWE | B8: =COUNTIF('2025'!F$3:F$123,Statistiques!A8) -> 0 | C8: =B8/B$13 -> 0
A9: IT | B9: =COUNTIF('2025'!F$3:F$123,Statistiques!A9) -> 0 | C9: =B9/B$13 -> 0
A10: CN | B10: =COUNTIF('2025'!F$3:F$123,Statistiques!A10) -> 0 | C10: =B10/B13 -> 0
A11: UAE | B11: =COUNTIF('2025'!F$3:F$123,Statistiques!A11) -> 0 | C11: =B11/B13 -> 0
A12: CA | B12: =COUNTIF('2025'!F$3:F$123,Statistiques!A12) -> 0 | C12: =B12/B$13 -> 0
A13: Total | B13: =SUM(B2:B12) -> 54 | C13: =SUM(C2:C12) -> 1
A15: Réception des demandes via
A16: SCIB | B16: {=SUMPRODUCT(('2025'!R3:R123="SCIB UK")+('2025'!R3:R123="SCIB FR")+('2025'!R3:R123="SCIB BE")+('2025'!R3:R123="SCIB NORDICS"))} -> 21 | C16: =B16/B$20 -> 0.53846154
A17: VP | B17: =COUNTIF('2025'!R3:R123,Statistiques!A17) -> 0 | C17: =B17/B$20 -> 0
A18: Direct | B18: =COUNTIF('2025'!R3:R123,"DIRECT") -> 17 | C18: =B18/B$20 -> 0.43589744
A19: Autre | B19: {=SUMPRODUCT(('2025'!R3:R123="Villars X")+('2025'!R3:R123="Autre"))} -> 1 | C19: =B19/B20 -> 0.025641026
A20: Total | B20: =SUM(B16:B19) -> 39 | C20: =SUM(C16:C19) -> 1
A23: Durée moyenne des séjours
A24: =AVERAGE('2025'!P3:P123) -> 899.68627
A26: Taille moyenne des groupes
A27: =AVERAGE('2025'!Q3:Q123) -> 86.55102
A29: Période à laquelle nous avons envoyé l'offre
A31: Janvier | B31: =COUNTIF('2025'!C3:C123,Statistiques!A31) -> 4 | C31: =B31/B43 -> 0.085106383
A32: Février | B32: =COUNTIF('2025'!C3:C123,Statistiques!A32) -> 3 | C32: =B32/B43 -> 0.063829787
A33: Mars | B33: =COUNTIF('2025'!C3:C123,Statistiques!A33) -> 0 | C33: =B33/B43 -> 0
A34: Avril | B34: =COUNTIF('2025'!C3:C123,Statistiques!A34) -> 6 | C34: =B34/B43 -> 0.12765957
A35: Mai | B35: =COUNTIF('2025'!C3:C123,Statistiques!A35) -> 1 | C35: =B35/B43 -> 0.021276596
A36: Juin | B36: =COUNTIF('2025'!C3:C123,Statistiques!A36) -> 3 | C36: =B36/B43 -> 0.063829787
A37: Juillet | B37: =COUNTIF('2025'!C3:C123,Statistiques!A37) -> 0 | C37: =B37/B43 -> 0
A38: Août | B38: =COUNTIF('2025'!C3:C123,Statistiques!A38) -> 7 | C38: =B38/B43 -> 0.14893617
A39: Septembre | B39: =COUNTIF('2025'!C3:C123,Statistiques!A39) -> 6 | C39: =B39/B43 -> 0.12765957
A40: Octobre | B40: =COUNTIF('2025'!C3:C123,Statistiques!A40) -> 8 | C40: =B40/B43 -> 0.17021277
A41: Novembre | B41: =COUNTIF('2025'!C3:C123,Statistiques!A41) -> 5 | C41: =B41/B43 -> 0.10638298
A42: Décembre | B42: =COUNTIF('2025'!C3:C123,Statistiques!A42) -> 4 | C42: =B42/B43 -> 0.085106383
A43: Total | B43: =SUM(B31:B42) -> 47 | C43: =SUM(C31:C42) -> 1
A45: Hiver | B45: =((SUM(B31:B34)+B42)/B43) -> 0.36170213
A46: Eté | B46: =(SUM(B35:B41)/B43) -> 0.63829787
B47: =B45+B46 -> 1
...

Sheet Listes automatisation
A1: Titre | B1: Langue | C1: Pays | D1: Activités VX | E1: Brevo | F1: Traité par | G1: Transmis par | H1: Mois d'envoie de l'offre et de venu
A2: M | B2: FR | C2: CH | D2: oui | E2: oui | F2: MP | G2: DIRECT (OT, AV, formulaire) | H2: Janvier
A3: Mme | B3: EN | C3: FR | D3: non | E3: déjà dans Brevo | F3: RC | G3: SCIB BE | H3: Février
B4: DE | C4: UK | F4: LL | G4: SCIB UK | H4: Mars
B5: BE | C5: BE | F5: GC | G5: SCIB FR | H5: Avril
C6: DE | G6: SCIB DE | H6: Mai
C7: PL | G7: AUTRE | H7: Juin
C8: CAN | G8: SCIB NORDICS | H8: Juillet
C9: CZ | G9: VP | H9: Août
C10: LUX | H10: Septembre
H11: Octobre
H12: Novembre
H13: Décembre
